<?xml version="1.0"?>
<robot name="urdfbot">

  <link name="base_link">
    <visual>        
      <geometry>
        <mesh filename="package://urdfbot_description/meshes/urdfbot_body.dae" scale="0.1 0.1 0.1"/>
      </geometry>
    </visual>

  <collision>
      <geometry>
        <mesh filename="package://urdfbot_description/meshes/urdfbot_body.dae" scale="0.1 0.1 0.1"/>
      </geometry>
  </collision>

    <inertial>
      <mass value="0.5" />
      <inertia ixx="0.0008333333333333335" ixy="0.0008333333333333335" ixz="00.0008333333333333335" iyy="0.0008333333333333335" iyz="0" izz="0.0008333333333333335"/>
    </inertial>

  </link>

  <link name="head_link">
    <visual>
    <origin rpy="0 0 0" xyz="0 0 0" />
      <geometry>
        <mesh filename="package://urdfbot_description/meshes/urdfbot_head.dae" scale="0.1 0.1 0.1"/>
      </geometry>
    </visual>
  </link>

    <joint name="base_link_to_head_link_joint" type="revolute">
        <origin xyz="0 0 0.07" rpy="0 0 0"/>
        <parent link="base_link"/>
        <child link="head_link"/>
        <axis xyz="0 0 1"/>
        <limit effort="100" velocity="1.0" lower="-1.57" upper="1.57"/>
    </joint>


    <!-- Right Arm -->

    <link name="upper_arm_r_link">
        <visual>
        <origin rpy="1.57 1.57 0" xyz="0 0 0" />
          <geometry>
              <mesh filename="package://urdfbot_description/meshes/arm.dae" scale="0.002 0.002 0.002"/>
          </geometry>
        </visual>

        <collision>
          <origin rpy="1.57 1.57 0" xyz="0 0 0" />
            <geometry>
              <mesh filename="package://urdfbot_description/meshes/arm.dae" scale="0.002 0.002 0.002"/>
            </geometry>
        </collision>

        <inertial>
          <mass value="0.01" />
          <origin rpy="1.57 1.57 0" xyz="0 0 0" />
          <inertia ixx="0.0008333333333333335" ixy="0.0008333333333333335" ixz="00.0008333333333333335" iyy="0.0008333333333333335" iyz="0" izz="0.0008333333333333335"/>
        </inertial>
    </link>

    <joint name="base_link_to_upper_arm_r_link_joint" type="revolute">
        <origin xyz="0 -0.03272 0.0279895" rpy="-1.57 0 0"/>
        <parent link="base_link"/>
        <child link="upper_arm_r_link"/>
        <axis xyz="0 0 1"/>
        <limit effort="100" velocity="1.0" lower="-1.5" upper="1.5"/>
    </joint>

    <link name="claw_a_r_link">
        <visual>
        <origin rpy="0 0 0" xyz="0 0 0" />
        <geometry>
            <mesh filename="package://urdfbot_description/meshes/direita.dae" scale="0.002 0.002 0.002"/>
        </geometry>
        </visual>
    </link>

    <joint name="upper_arm_r_link_to_claw_a_r_link_joint" type="revolute">
        <origin xyz="0.16 -0.02 0.02" rpy="1.57 1.57 0"/>
        <parent link="upper_arm_r_link"/>
        <child link="claw_a_r_link"/>
        <axis xyz="0 0 1"/>
        <limit effort="100" velocity="1.0" lower="-0.7" upper="0"/>
    </joint>

    <link name="claw_b_r_link">
        <visual>
        <origin rpy="0 0 0" xyz="0 0 0" />
        <geometry>
            <mesh filename="package://urdfbot_description/meshes/esquerda.dae" scale="0.002 0.002 0.002"/>
        </geometry>
        </visual>
    </link>

    <joint name="upper_arm_r_link_to_claw_b_r_link_joint" type="revolute">
        <origin xyz="0.16 -0.02 0.02" rpy="1.57 1.57 0"/>
        <parent link="upper_arm_r_link"/>
        <child link="claw_b_r_link"/>
        <axis xyz="0 0 1"/>
        <limit effort="100" velocity="1.0" lower="0.0" upper="0.0"/>
        <mimic joint="upper_arm_r_link_to_claw_a_r_link_joint" multiplier="-1.0" offset="0.0"/>
    </joint>




<!-- Position Config -->
    <ros2_control name="GazeboSystem" type="system">
      <hardware>
        <plugin>gazebo_ros2_control/GazeboSystem</plugin>
      </hardware>

      <joint name="base_link_to_upper_arm_r_link_joint">
        <command_interface name="position">
          <param name="min">-1.57</param>
          <param name="max">1.57</param>
        </command_interface>
        <state_interface name="position"/>
        <state_interface name="velocity"/>
        <state_interface name="effort"/>
      </joint>

  </ros2_control>


  <gazebo>
    <plugin filename="libgazebo_ros2_control.so" name="gazebo_ros2_control">
      <parameters>$(find urdfbot_description)/config/controller_position.yaml</parameters>
      <robot_param_node>/insperbot_garra_state_publisher_node</robot_param_node>
    </plugin>
  </gazebo>


</robot>